Workbook

Sheet README
A1: THE UNLOX ACADEMY - DA/DS TRACK
A2: Excel Minor Project - Sales Operations Analytics
A3: Interview-Grade Data Analytics Assessment · 100 Marks
A5: THE SCENARIO
A6: You have just joined the analytics team at a fast-growing multi-category retailer operating across 6 Indian cities.
A7: The head of sales has handed you 5 raw data files - Orders, Customers, Products, Sales Reps, and Targets - and asked
A8: you to answer a set of business questions before the leadership review tomorrow morning.
A10: The data is REAL-WORLD messy: duplicates, missing references, inconsistent case, invalid records, discontinued SKUs.
A11: Part of the assessment is spotting and handling these issues correctly. A wrong-looking answer isn't always wrong -
A12: sometimes the data itself is telling a story.
A14: RULES OF THE ASSESSMENT
A15: 1. Write your answer in the YELLOW cells on each question sheet. Empty answer cell = 0 marks.
... A22: MARKS DISTRIBUTION
A23: Section | B23: Topic | C23: Questions | D23: Marks
A24: Q1 | B24: Lookup Functions (VLOOKUP, INDEX-MATCH, chained lookups) | C24: 8 | D24: 25
A25: Q2 | B25: Data Cleaning & Quality Diagnostics | C25: 6 | D25: 20
A26: Q3 | B26: Conditional Aggregation (SUMIFS, COUNTIFS, IF logic) | C26: 6 | D26: 25
A27: Q4 | B27: Pivot Tables (2D pivots, % of total, calculated fields) | C27: 5 | D27: 20
A28: Q5 | B28: Advanced (Ranking, Running Totals, Multi-condition) | C28: 5 | D28: 10
B29: TOTAL | C29: 30 | D29: 100
A32: PERFORMANCE TIERS
A33: Marks | B33: Tier | C33: Interview Verdict
A34: 85 - 100 | B34: Excellent | C34: Round 1 clear - Excel not a concern
A35: 70 - 84 | B35: Good | C35: Round 1 clear with minor gaps
A36: 55 - 69 | B36: Borderline | C36: Round 1 uncertain - needs revision
A37: 40 - 54 | B37: Weak | C37: Round 1 likely reject - 2 weeks of practice needed
A38: < 40 | B38: Insufficient | C38: Round 1 reject - foundational gaps
A41: DATA SHEETS OVERVIEW
A42: Sheet | B42: Rows | C42: Key Columns | D42: Joins to
A43: Orders | B43: ~2000 | C43: order_id, order_date, customer_id, product_id, sales_rep_id, quantity, unit_price, discount_pct, final_amount, payment_status, ship_city | D43: All others
A44: Customers | B44: 300 | C44: customer_id (PK), customer_name, age, city, segment, signup_date | D44: Orders via customer_id
A45: Products | B45: 60 | C45: product_id (PK), product_name, category, unit_cost, unit_price, is_active | D45: Orders via product_id
A46: Sales_Reps | B46: 30 | C46: rep_id (PK), rep_name, region, hire_date, team_lead_id | D46: Orders via sales_rep_id, self-join via team_lead_id
A47: Targets | B47: 30 × 12 | C47: rep_id (PK), Jan-24 through Dec-24 monthly target values | D47: Sales_Reps via rep_id

Sheet Orders
A1: order_id | B1: order_date | C1: customer_id | D1: product_id | E1: sales_rep_id | F1: quantity | G1: unit_price | H1: discount_pct | I1: final_amount | J1: payment_status | K1: ship_city
A2: ORD-00001 | B2: 45549 | C2: CUST-0243 | D2: PROD-014 | E2: R007 | F2: 8 | G2: 3620 | H2: 15.4 | I2: 24500.16 | J2: Completed | K2: Pune
A3: ORD-00002 | B3: 45340 | C3: CUST-0202 | D3: PROD-020 | E3: R005 | F3: 2 | G3: 820 | H3: 10.8 | I3: 1462.88 | J3: Pending | K3: Chennai
A4: ORD-00003 | B4: 45371 | C4: CUST-0098 | D4: PROD-053 | E4: R014 | F4: 8 | G4: 470 | H4: 3.3 | I4: 3635.92 | J4: Pending | K4: Delhi
A5: ORD-00004 | B5: 45413 | C5: CUST-0071 | D5: PROD-028 | E5: R006 | F5: 1 | G5: 3660 | H5: 15.7 | I5: 3085.38 | J5: Completed | K5: Delhi
A6: ORD-00005 | B6: 45611 | C6: CUST-0180 | D6: PROD-012 | E6: R008 | F6: 1 | G6: 3160 | H6: 26 | I6: 2338.4 | J6: Completed | K6: Chennai
A7: ORD-00006 | B7: 45406 | C7: CUST-0275 | D7: PROD-032 | E7: R025 | F7: 4 | G7: 370 | H7: 29 | I7: 1050.8 | J7: Completed | K7: Mumbai
A8: ORD-00007 | B8: 45455 | C8: CUST-0293 | D8: PROD-057 | E8: R024 | F8: 3 | G8: 960 | H8: 5.8 | I8: 2712.96 | J8: Completed | K8: Bengaluru
A9: ORD-00008 | B9: 45617 | C9: CUST-0281 | D9: PROD-007 | E9: R019 | F9: 8 | G9: 1430 | H9: 2.4 | I9: 11165.44 | J9: Completed | K9: Bengaluru
A10: ORD-00009 | B10: 45549 | C10: CUST-0260 | D10: PROD-038 | E10: R008 | F10: 3 | G10: 5490 | H10: 14.2 | I10: 14131.26 | J10: Completed | K10: Bengaluru
A11: ORD-00010 | B11: 45396 | C11: CUST-0147 | D11: PROD-030 | E11: R028 | F11: 3 | G11: 970 | H11: 1.2 | I11: 2875.08 | J11: Completed | K11: Pune
A12: ORD-00011 | B12: 45560 | C12: CUST-0204 | D12: PROD-024 | E12: R010 | F12: 7 | G12: 2270 | H12: 7.1 | I12: 14761.81 | J12: Pending | K12: Hyderabad
A13: ORD-00012 | B13: 45332 | C13: CUST-0147 | D13: PROD-010 | E13: R024 | F13: 9 | G13: 2640 | H13: 21.7 | I13: 18604.08 | J13: Completed | K13: Pune
... A2001: ORD-02000 | B2001: 45325 | C2001: CUST-0238 | D2001: PROD-034 | E2001: R023 | F2001: 6 | G2001: 5080 | H2001: 28.1 | I2001: 21915.12 | J2001: Completed | K2001: Delhi

Sheet Customers
A1: customer_id | B1: customer_name | C1: age | D1: city | E1: segment | F1: signup_date
A2: CUST-0001 | B2: Amit Agarwal | C2: 36 | D2: Pune | E2: Retail | F2: 44819
A3: CUST-0002 | B3: Vihaan Malhotra | C3: 42 | D3: Pune | E3: Corporate | F3: 44984
A4: CUST-0003 | B4: Navya Malhotra | C4: 33 | D4: Mumbai | E4: Retail | F4: 44059
A5: CUST-0004 | B5: Aaradhya Mehta | C5: 53 | D5: delhi | E5: Retail | F5: 44054
A6: CUST-0005 | B6: Myra Malhotra | C6: 52 | D6: Chennai | E6: Corporate | F6: 45037
A7: CUST-0006 | B7: Shaurya Iyer | C7: 44 | D7: Pune | E7: SMB | F7: 44302
A8: CUST-0007 | B8: Dhruv Joshi | C8: 47 | D8: Bengaluru | E8: Retail | F8: 44498
A9: CUST-0008 | B9: Kavita Malhotra | C9: 39 | D9: Pune | E9: SMB | F9: 45162
A10: CUST-0009 | B10: Neha Malhotra | C10: 61 | D10: Mumbai | E10: Retail | F10: 44343
A11: CUST-0010 | B11: Aaradhya Gupta | C11: 61 | D11: Mumbai | E11: SMB | F11: 44975
A12: CUST-0011 | B12: Diya Menon | C12: 41 | D12: Chennai | E12: Corporate | F12: 44821
A13: CUST-0012 | B13: Prisha Desai | C13: 43 | D13: Pune | E13: Retail | F13: 44718
... A301: CUST-0300 | B301: Rohit Nair | C301: 38 | D301: Mumbai | E301: Retail | F301: 43932

Sheet Products
A1: product_id | B1: product_name | C1: category | D1: unit_cost | E1: unit_price | F1: is_active
A2: PROD-001 | B2: Smartphone Pro | C2: Electronics | D2: 2405 | E2: 5330 | F2: TRUE
A3: PROD-002 | B3: Wireless Earbuds | C3: Electronics | D3: 1052 | E3: 2600 | F3: TRUE
A4: PROD-003 | B4: Smart Watch | C4: Electronics | D4: 1665 | E4: 3570 | F4: TRUE
A5: PROD-004 | B5: Laptop Bag | C5: Electronics | D5: 1559 | E5: 3870 | F5: TRUE
A6: PROD-005 | B6: Power Bank | C6: Electronics | D6: 128 | E6: 300 | F6: TRUE
A7: PROD-006 | B7: Bluetooth Speaker | C7: Electronics | D7: 2865 | E7: 3970 | F7: TRUE
A8: PROD-007 | B8: USB-C Cable | C8: Electronics | D8: 861 | E8: 1430 | F8: TRUE
A9: PROD-008 | B9: Wireless Mouse | C9: Electronics | D9: 1259 | E9: 2660 | F9: FALSE
A10: PROD-009 | B10: Mechanical Keyboard | C10: Electronics | D10: 517 | E10: 1220 | F10: TRUE
A11: PROD-010 | B11: Tablet Stand | C11: Electronics | D11: 1149 | E11: 2640 | F11: TRUE
A12: PROD-011 | B12: Cotton T-Shirt | C12: Apparel | D12: 1748 | E12: 3450 | F12: TRUE
A13: PROD-012 | B13: Denim Jeans | C13: Apparel | D13: 1886 | E13: 3160 | F13: TRUE
... A61: PROD-060 | B61: Gym Gloves | C61: Sports | D61: 147 | E61: 190 | F61: TRUE

Sheet Sales_Reps
A1: rep_id | B1: rep_name | C1: region | D1: hire_date | E1: team_lead_id
A2: R001 | B2: Rajesh Malhotra | C2: North | D2: 44207
A3: R002 | B3: Sunita Malhotra | C3: North | D3: 44028
A4: R003 | B4: Amit Singh | C4: North | D4: 43651
A5: R004 | B5: Priya Singh | C5: North | D5: 44907
A6: R005 | B6: Vikram Patel | C6: North | D6: 43588 | E6: R001
A7: R006 | B7: Neha Desai | C7: North | D7: 44131 | E7: R001
A8: R007 | B8: Suresh Menon | C8: North | D8: 43493 | E8: R001
A9: R008 | B9: Kavita Patel | C9: North | D9: 44693 | E9: R001
A10: R009 | B10: Manoj Patel | C10: South | D10: 44804 | E10: R002
A11: R010 | B11: Divya Rao | C11: South | D11: 43904 | E11: R002
A12: R011 | B12: Anil Verma | C12: South | D12: 44622 | E12: R002
A13: R012 | B13: Pooja Nair | C13: South | D13: 44890 | E13: R002
A14: R013 | B14: Sanjay Kapoor | C14: South | D14: 45215 | E14: R002
A15: R014 | B15: Ritu Menon | C15: South | D15: 44469 | E15: R002
A16: R015 | B16: Deepak Shah | C16: South | D16: 45231 | E16: R002
A17: R016 | B17: Anjali Chopra | C17: South | D17: 43614 | E17: R002
... A31: R030 | B31: Kiran Bhatt | C31: West | D31: 44506 | E31: R004

Sheet Targets
A1: rep_id | B1: Jan-24 | C1: Feb-24 | D1: Mar-24 | E1: Apr-24 | F1: May-24 | G1: Jun-24 | H1: Jul-24 | I1: Aug-24 | J1: Sep-24 | K1: Oct-24 | L1: Nov-24 | M1: Dec-24
A2: R001 | B2: 231324 | C2: 171682 | D2: 234376 | E2: 326967 | F2: 350588 | G2: 385324 | H2: 307980 | I2: 327947 | J2: 181016 | K2: 374039 | L2: 212805 | M2: 405999
A3: R002 | B3: 438126 | C3: 346266 | D3: 329993 | E3: 370744 | F3: 294660 | G3: 341556 | H3: 151934 | I3: 223794 | J3: 438641 | K3: 344308 | L3: 296172 | M3: 304288
A4: R003 | B4: 358703 | C4: 320519 | D4: 327321 | E4: 298753 | F4: 254636 | G4: 351929 | H4: 264723 | I4: 216459 | J4: 391945 | K4: 362426 | L4: 289199 | M4: 301863
A5: R004 | B5: 389594 | C5: 376422 | D5: 324156 | E5: 420255 | F5: 409107 | G5: 269954 | H5: 179097 | I5: 370568 | J5: 387395 | K5: 243454 | L5: 232530 | M5: 201999
A6: R005 | B6: 436862 | C6: 391158 | D6: 340224 | E6: 170548 | F6: 229390 | G6: 349525 | H6: 154683 | I6: 320848 | J6: 354452 | K6: 377180 | L6: 342347 | M6: 183362
A7: R006 | B7: 348734 | C7: 358191 | D7: 250385 | E7: 219657 | F7: 249365 | G7: 435704 | H7: 260892 | I7: 250741 | J7: 358402 | K7: 379858 | L7: 213280 | M7: 224634
A8: R007 | B8: 280057 | C8: 330342 | D8: 336856 | E8: 227425 | F8: 233647 | G8: 307088 | H8: 370724 | I8: 440008 | J8: 406347 | K8: 217357 | L8: 299289 | M8: 214568
A9: R008 | B9: 252886 | C9: 206057 | D9: 318209 | E9: 411230 | F9: 448660 | G9: 171135 | H9: 305339 | I9: 432264 | J9: 294273 | K9: 371409 | L9: 284207 | M9: 437068
A10: R009 | B10: 268752 | C10: 393256 | D10: 310649 | E10: 246237 | F10: 271287 | G10: 314545 | H10: 406506 | I10: 334930 | J10: 348625 | K10: 408928 | L10: 243749 | M10: 418409
A11: R010 | B11: 384734 | C11: 156698 | D11: 283679 | E11: 276085 | F11: 409270 | G11: 285230 | H11: 304233 | I11: 178221 | J11: 284216 | K11: 287373 | L11: 229082 | M11: 298969
A12: R011 | B12: 186029 | C12: 151419 | D12: 253251 | E12: 379757 | F12: 204209 | G12: 179396 | H12: 378008 | I12: 182649 | J12: 267772 | K12: 350352 | L12: 358042 | M12: 359960
A13: R012 | B13: 352158 | C13: 251181 | D13: 321255 | E13: 300863 | F13: 241731 | G13: 393275 | H13: 313561 | I13: 283604 | J13: 429065 | K13: 194420 | L13: 254168 | M13: 389283
... A31: R030 | B31: 151584 | C31: 221679 | D31: 385157 | E31: 290386 | F31: 236041 | G31: 407985 | H31: 184446 | I31: 342894 | J31: 180344 | K31: 292917 | L31: 314858 | M31: 364057

Sheet Q1_Lookups
A1: Q1 - LOOKUP FUNCTIONS (25 marks total)
A4: Q# | B4: Question | C4: Marks | D4: Hint | E4: Your Answer | F4: Format
A5: Q1.1 | B5: For order ORD-00234, what is the customer_id? | C5: 3 | D5: Simple VLOOKUP on Orders sheet. | E5: =VLOOKUP("ORD-00234",Orders!A2:C2001,3,FALSE) -> CUST-0173 | F5: CUST-####
A6: Q1.2 | B6: For order ORD-00456, what is the product_name? (You will need to look up the product_id first, then find its name in Products.) | C6: 3 | D6: Two-step lookup, or nested VLOOKUP. | E6: =VLOOKUP(VLOOKUP("ORD-00456",Orders!A2:D2001,4,FALSE),Products!A2:B61,2,FALSE) -> Dumbbells 5kg | F6: Text
A7: Q1.3 | B7: For order ORD-00987, what is the rep_name of the sales rep? Note: the rep_name is in a column that appears to the LEFT of what you might look up first. | C7: 3 | D7: VLOOKUP has directional limits - INDEX/MATCH does not. | E7: =INDEX(Sales_Reps!B2:B31,MATCH(VLOOKUP("ORD-00987",Orders!A2:E2001,5,FALSE),Sales_Reps!A2:A31,0)) -> Nisha Menon | F7: Text
A8: Q1.4 | B8: From the Targets sheet, what is the target value for rep R012 in the month Mar-24? | C8: 4 | D8: Two-way lookup: row = rep_id, column = month. | E8: =INDEX(Targets!B2:M31,MATCH("R012",Targets!A2:A31,0),MATCH("Mar-24",Targets!B1:M1,0)) -> 321255 | F8: Whole number
A9: Q1.5 | B9: For order ORD-01500, what is the CATEGORY of the product ordered? (Chain: order → product_id → category) | C9: 4 | D9: Multi-hop lookup across sheets. | E9: =VLOOKUP(VLOOKUP("ORD-01500",Orders!A2:D2001,4,FALSE),Products!A2:C61,3,FALSE) -> Electronics | F9: Text
A10: Q1.6 | B10: For order ORD-00789, which DISCOUNT SLAB does it fall in? Use the slab table below (rows 20-24). Slab breakpoints are the LOWER bound of each range. | C10: 3 | D10: Approximate-match VLOOKUP (sort ascending, TRUE / omit last arg). | E10: =VLOOKUP(VLOOKUP("ORD-00789",Orders!A2:H2001,8,FALSE),$B$18:$C$21,2,TRUE) -> Bronze | F10: Text
A11: Q1.7 | B11: For order ORD-01234, in one cell produce the string: "<rep_name> (<sales_region>)" - e.g. "Amit Singh (South)". | C11: 3 | D11: Two lookups joined with & or CONCATENATE. | E11: =VLOOKUP(VLOOKUP("ORD-01234",Orders!A2:E2001,5,FALSE),Sales_Reps!A2:C31,2,FALSE)&" ("&VLOOKUP(VLOOKUP("ORD-01234",Orders!A2:E2001,5,FALSE),Sales_Reps!A2:C31,3,FALSE)&")" -> Sanjay Kapoor (South) | F11: Text
A12: Q1.8 | B12: What is the rep_name of the TEAM LEAD for rep R017? (The Sales_Reps sheet has team_lead_id - you need to self-join to find that person's name.) | C12: 2 | D12: Look up the team_lead_id, then look up THAT id's rep_name. | E12: =VLOOKUP(VLOOKUP("R017",Sales_Reps!A2:E31,5,FALSE),Sales_Reps!A2:B31,2,FALSE) -> Amit Singh | F12: Text
B15: DISCOUNT SLAB REFERENCE TABLE (use for Q1.6)
B17: Discount % (Lower) | C17: Slab
B18: 0 | C18: Bronze
B19: 5 | C19: Silver
B20: 15 | C20: Gold
B21: 25 | C21: Platinum

Sheet Q2_Cleaning
A1: Q2 - DATA CLEANING & QUALITY DIAGNOSTICS (20 marks total)
A2: Duplicates · Whitespace · Case Inconsistency · Referential Integrity · Discontinued SKUs · Anomaly Patterns
A4: Q# | B4: Question | C4: Marks | D4: Hint | E4: Your Answer | F4: Format
A5: Q2.1 | B5: How many DUPLICATE rows exist in the Orders sheet (i.e., how many order_id values appear more than once)? Count each duplicate as ONE (not the extras). | C5: 3 | D5: COUNTIF > 1, then count. Watch what you're counting - rows or IDs. | E5: {=SUMPRODUCT((COUNTIF(Orders!$A$2:$A$2001,Orders!$A$2:$A$2001)>1)/COUNTIF(Orders!$A$2:$A$2001,Orders!$A$2:$A$2001))} -> 20 | F5: Whole number
A6: Q2.2 | B6: How many customers in the Customers sheet have LEADING or TRAILING whitespace in their customer_name? | C6: 3 | D6: Compare LEN vs LEN(TRIM). Or use SUMPRODUCT with a boolean. | E6: {=SUMPRODUCT(--(LEN(Customers!B2:B301)<>LEN(TRIM(Customers!B2:B301))))} -> 15 | F6: Whole number
A7: Q2.3 | B7: The Customers sheet has some cities in inconsistent case (e.g., "mumbai", "MUMBAI", "Mumbai"). How many DISTINCT cities exist AFTER standardizing case? | C7: 3 | D7: Combine PROPER/UPPER with a de-dup count. SUMPRODUCT + 1/COUNTIF trick works. | E7: {=SUMPRODUCT(1/COUNTIF(Customers!D2:D301,Customers!D2:D301))} -> 6 | F7: Whole number
A8: Q2.4 | B8: How many orders reference a customer_id that DOES NOT EXIST in the Customers sheet? (Broken foreign key) | C8: 4 | D8: Use MATCH with ISNA/ISERROR, then count. | E8: {=SUMPRODUCT(--ISNA(MATCH(Orders!C2:C2001,Customers!A2:A301,0)))} -> 30 | F8: Whole number
A9: Q2.5 | B9: How many orders reference a product that is currently DISCONTINUED (is_active = FALSE in the Products sheet)? | C9: 3 | D9: VLOOKUP the is_active flag, then count where FALSE. | E9: {=SUMPRODUCT(COUNTIF(Orders!D2:D2001,Products!A2:A61)*--(Products!F2:F61=FALSE))} -> 174 | F9: Whole number
A10: Q2.6 | B10: Find the "suspicious pattern": how many orders have payment_status = "Cancelled" AND a discount_pct > 20%? (This pattern often indicates promo abuse - a real-world diagnostic query.) | C10: 4 | D10: COUNTIFS with two criteria. | E10: =COUNTIFS(Orders!J2:J2001,"Cancelled",Orders!H2:H2001,">20") -> 58 | F10: Whole number

Sheet Q3_Aggregation
A1: Q3 - CONDITIONAL AGGREGATION (25 marks total)
A2: SUMIFS · COUNTIFS · AVERAGEIFS · Nested IF logic · Multi-sheet aggregation · Top-N logic
A4: Q# | B4: Question | C4: Marks | D4: Hint | E4: Your Answer | F4: Format
A5: Q3.1 | B5: What is the TOTAL REVENUE (sum of final_amount) for orders in Q3 2024 (Jul-Sep) where ship_city is Mumbai? | C5: 4 | D5: SUMIFS with 3 conditions: date >= start, date <= end, city = Mumbai. Beware case issues. | E5: =SUMIFS(Orders!I2:I2001,Orders!B2:B2001,">="&DATE(2024,7,1),Orders!B2:B2001,"<"&DATE(2024,10,1),Orders!K2:K2001,"Mumbai") -> 1217239 | F5: Currency
A6: Q3.2 | B6: How many orders have discount_pct > 15% AND payment_status = "Completed"? | C6: 3 | D6: COUNTIFS with two conditions. | E6: =COUNTIFS(Orders!H2:H2001,">15",Orders!J2:J2001,"Completed") -> 723 | F6: Whole number
A7: Q3.3 | B7: What is the AVERAGE final_amount for orders where the product CATEGORY is "Electronics" AND the customer SEGMENT is "Corporate"? Note: Both fields come from OTHER sheets - you'll need helper columns. | C7: 5 | D7: Helper columns in Orders: VLOOKUP category from Products, VLOOKUP segment from Customers. Then AVERAGEIFS. | E7: =AVERAGEIFS(Q3_Working!C2:C2001,Q3_Working!E2:E2001,"Electronics",Q3_Working!F2:F2001,"Corporate") -> 13981.402 | F7: Currency
A8: Q3.4 | B8: What is the COMBINED REVENUE of the TOP 3 reps by total revenue? (Sum of the 3 highest rep totals.) | C8: 4 | D8: Compute per-rep totals, then use SUMPRODUCT with LARGE, or sort and sum top 3. | E8: =SUM(LARGE(Q3_Working!K2:K31,1),LARGE(Q3_Working!K2:K31,2),LARGE(Q3_Working!K2:K31,3)) -> 3342678.5 | F8: Currency
A9: Q3.5 | B9: For rep R015 in Nov-24: compute the actual revenue and compare to the target (from Targets sheet). Report the PERFORMANCE TIER using: <80% → "Below", 80-120% → "On Track", >120% → "Exceeds". Return only the tier text. | C9: 5 | D9: Nested IF (or IFS): compute actual/target ratio, then classify. | E9: =IF(Q3_Working!K34/Q3_Working!K35<0.8,"Below",IF(Q3_Working!K34/Q3_Working!K35<=1.2,"On Track","Exceeds")) -> Below | F9: Text
A10: Q3.6 | B10: What is the TOTAL revenue from Corporate segment customers aged between 30 and 40 (both inclusive)? | C10: 4 | D10: Helper columns for age and segment. Then SUMIFS with numeric range. | E10: =SUMIFS(Q3_Working!C2:C2001,Q3_Working!F2:F2001,"Corporate",Q3_Working!G2:G2001,">=30",Q3_Working!G2:G2001,"<=40") -> 982568.4 | F10: Currency

Sheet Sheet2
A1: Regional Sales Performance Chart
B3: Column Labels
A4: Row Labels | B4: Apparel | C4: Beauty | D4: Electronics | E4: Grocery | F4: Home | G4: Sports | H4: Grand Total
A5: East | B5: 860762.23 | C5: 1271152.8 | D5: 1214881.9 | E5: 1168089.9 | F5: 1124233.5 | G5: 945710.08 | H5: 6584830.5
A6: North | B6: 979380.97 | C6: 1556120.2 | D6: 1450710.7 | E6: 1118963.8 | F6: 867033.27 | G6: 1011820.5 | H6: 6984029.5
A7: South | B7: 962768.31 | C7: 1590646.1 | D7: 1314107.4 | E7: 1041400.8 | F7: 1140277.8 | G7: 1095843.5 | H7: 7145043.8
A8: West | B8: 868240.03 | C8: 1188460 | D8: 993053.05 | E8: 997265.82 | F8: 955407.58 | G8: 856617.89 | H8: 5859044.4
A9: Grand Total | B9: 3671151.5 | C9: 5606379.1 | D9: 4972753.1 | E9: 4325720.4 | F9: 4086952.2 | G9: 3909991.9 | H9: 26572948

Sheet Sheet3
A3: Sum of Final Amount | B3: Column Labels
A4: Row Labels | B4: 45292 | C4: 45323 | D4: 45352 | E4: 45383 | F4: 45413 | G4: 45444 | H4: 45474 | I4: 45505 | J4: 45536 | K4: 45566 | L4: 45597 | M4: 45627 | N4: Grand Total
A5: R001 | B5: 43650.56 | C5: 127005.17 | D5: 58208.49 | E5: 33643.48 | F5: 44809.66 | G5: 82789.95 | H5: 28761.2 | I5: 92676.92 | J5: 88884.34 | K5: 37753.9 | L5: 72215.41 | M5: 79450.52 | N5: 789849.6
A6: R002 | B6: 51707.32 | C6: 125187.78 | D6: 53533 | E6: 46286.92 | F6: 89794.86 | G6: 82753.37 | H6: 62949.74 | I6: 134500.5 | J6: 91647.29 | K6: 35751.81 | L6: 158277.82 | M6: 47673.25 | N6: 980063.66
A7: R003 | B7: 54307 | C7: 32452 | D7: 107489.23 | E7: 96349.86 | F7: 139257.72 | G7: 37966.09 | H7: 185921.75 | I7: 114656.27 | J7: 69896.72 | K7: 29309.98 | L7: 106760.75 | M7: 12325.54 | N7: 986692.91
A8: R004 | B8: 57892.11 | C8: 58818.56 | D8: 14394.38 | E8: 23036.54 | F8: 140739.8 | G8: 42388.12 | H8: 7823.48 | I8: 55975.34 | J8: 46944.28 | K8: 43456.18 | L8: 38491.18 | M8: 59066.32 | N8: 589026.29
A9: R005 | B9: 70665.51 | C9: 57914.81 | D9: 85853.43 | E9: 46025.56 | F9: 67702.82 | G9: 113205.32 | H9: 20649.35 | I9: 15060.28 | J9: 81963.69 | K9: 99252.77 | L9: 55570.99 | M9: 68580.8 | N9: 782445.33
A10: R006 | B10: 84968.56 | C10: 34581.99 | D10: 145435.13 | E10: 170939.91 | F10: 78322.48 | G10: 191251.6 | H10: 38479.32 | I10: 61857.9 | J10: 76627.83 | K10: 52942.27 | L10: 81500.24 | M10: 121741.5 | N10: 1138648.7
A11: R007 | B11: 92029.91 | C11: 130276.04 | D11: 105489.83 | E11: 48536.18 | F11: 41157.84 | G11: 58895.11 | H11: 11528.24 | I11: 70196.8 | J11: 52194.15 | K11: 57313.75 | L11: 130208.9 | M11: 57922.93 | N11: 855749.68
A12: R008 | B12: 61557.02 | C12: 23463.3 | D12: 164615.05 | E12: 12044.56 | F12: 67200.57 | G12: 82481.44 | H12: 75853.47 | I12: 61043.44 | J12: 49404.64 | K12: 26620.46 | L12: 64537.26 | M12: 172732.12 | N12: 861553.33
A13: R009 | B13: 125547.54 | C13: 25935.55 | D13: 19130.39 | E13: 74565.16 | F13: 100231.54 | G13: 69794.65 | H13: 99012.62 | I13: 116575.85 | J13: 98466.52 | K13: 107648.92 | L13: 30954.96 | M13: 46691.02 | N13: 914554.72
A14: R010 | B14: 43078.21 | C14: 74555.64 | E14: 41398.06 | F14: 83732.94 | G14: 29458.16 | H14: 96008.48 | I14: 111335.79 | J14: 146100.57 | K14: 64630.99 | L14: 119201.57 | M14: 70844.79 | N14: 880345.2
A15: R011 | B15: 88791.72 | C15: 112894.06 | D15: 77891.76 | E15: 30549.1 | F15: 10392.16 | G15: 45625.44 | H15: 31373.22 | I15: 129473.96 | J15: 88472.06 | K15: 55503.48 | L15: 64240.8 | N15: 735207.76
A16: R012 | B16: 70680.03 | C16: 110195.46 | D16: 20450.24 | E16: 24950.8 | F16: 37183.63 | G16: 59218.28 | H16: 75017.78 | I16: 115185.59 | J16: 104717.03 | K16: 89150.85 | L16: 69152.06 | M16: 125492.57 | N16: 901394.32
A17: R013 | B17: 51609.12 | C17: 139218.08 | D17: 80024.44 | E17: 41420.61 | F17: 80787.31 | G17: 33836.58 | H17: 32733.74 | I17: 70557.86 | J17: 63389.33 | K17: 46714.58 | L17: 108112.07 | M17: 63120.66 | N17: 811524.38
A18: R014 | B18: 87497.74 | C18: 79488 | D18: 85611.84 | E18: 101517.17 | F18: 154170.2 | G18: 15951.6 | H18: 74760.15 | I18: 113977.94 | J18: 45673.51 | K18: 80097.18 | L18: 50971.92 | M18: 105996.29 | N18: 995713.54
A19: R015 | B19: 118901.06 | C19: 89654.68 | D19: 67837.49 | E19: 107626.6 | F19: 146185.96 | G19: 12840.4 | H19: 51083.42 | I19: 114985.86 | J19: 92815.3 | K19: 119179.18 | L19: 97394.65 | M19: 73235.58 | N19: 1091740.2
A20: R016 | B20: 62195.84 | C20: 90583.24 | D20: 153834.45 | E20: 75094.84 | F20: 67937.96 | G20: 55791.51 | H20: 70547.11 | I20: 119357.27 | J20: 34105.56 | K20: 55604.09 | L20: 26689.96 | M20: 2821.88 | N20: 814563.71
A21: R017 | B21: 73856.39 | C21: 27297.84 | D21: 120293.66 | E21: 32212.65 | F21: 113791.15 | G21: 73782.34 | H21: 4516.7 | I21: 88015.95 | J21: 75893.02 | K21: 75670.28 | L21: 23417.13 | M21: 71637.3 | N21: 780384.41
A22: R018 | B22: 101638.5 | C22: 121362.44 | D22: 51595.62 | E22: 210613.93 | F22: 173129.47 | G22: 117809.47 | H22: 41039.88 | I22: 26814.3 | J22: 29070.76 | K22: 109087.31 | L22: 84868.64 | M22: 45259.32 | N22: 1112289.6
A23: R019 | B23: 30895.18 | C23: 97513.34 | D23: 68954.54 | E23: 112510.04 | F23: 58746.86 | G23: 107491.78 | H23: 72372.48 | I23: 20666.8 | J23: 34590.78 | K23: 152548.56 | L23: 96634.5 | M23: 118258.66 | N23: 971183.52
A24: R020 | B24: 41744.44 | C24: 13855.82 | D24: 215416.3 | E24: 49921.2 | F24: 182980.03 | G24: 90724.13 | H24: 28955.71 | I24: 107718.33 | J24: 57555.72 | K24: 23378.26 | L24: 68985.01 | M24: 24872.76 | N24: 906107.71
A25: R021 | B25: 2689.92 | C25: 104662.05 | D25: 100685.62 | E25: 71054.8 | F25: 56143.78 | G25: 65924.82 | H25: 72167.3 | I25: 44212.2 | J25: 108409.59 | K25: 42203.75 | L25: 53126.1 | M25: 40227.24 | N25: 761507.17
A26: R022 | B26: 158207.84 | C26: 46819.11 | D26: 51327.36 | E26: 93303.02 | F26: 8802.79 | G26: 61415.64 | H26: 210918.24 | I26: 81133.64 | J26: 87991.22 | K26: 73388.56 | L26: 76504.66 | M26: 119758.46 | N26: 1069570.5
A27: R023 | B27: 54606.06 | C27: 120382.87 | D27: 82920.6 | E27: 216421.52 | F27: 40444.23 | G27: 102315.15 | H27: 89062.99 | I27: 50585.6 | J27: 50462.58 | K27: 13975.5 | L27: 59984.34 | M27: 102626.04 | N27: 983787.48
... A35: Grand Total | B35: 1941147.4 | C35: 2307493.7 | D35: 2480322.6 | E35: 2282454.1 | F35: 2580391 | G35: 1965939.1 | H35: 1965013.7 | I35: 2527928 | J35: 2062815.6 | K35: 1977882.4 | L35: 2297637.1 | M35: 2183923.5 | N35: 26572948

Sheet Q3_Working
A1: Order ID | B1: Order Date | C1: Final Amount | D1: Sales Rep ID | E1: Category | F1: Segment | G1: Age | H1: Sales Region | I1: Order Month | J1: Rep ID | K1: Total Revenue | L1: Ship City | M1: Unit Price | N1: Unit Cost | O1: Profit Margin | P1: Revenue Rank | Q1: Product ID | R1: Product List | S1: West Revenue | T1: Rank | U1: Rep Name
A2: =Orders!A2 -> ORD-00001 | B2: =Orders!B2 -> 45549 | C2: =Orders!I2 -> 24500.16 | D2: =Orders!E2 -> R007 | E2: =IFERROR(VLOOKUP(Orders!D2,Products!$A$2:$C$61,3,FALSE),"Unknown") -> Apparel | F2: =IFERROR(VLOOKUP(Orders!C2,Customers!$A$2:$E$301,5,FALSE),"Unknown") -> SMB | G2: =IFERROR(VLOOKUP(Orders!C2,Customers!$A$2:$C$301,3,FALSE),"") -> 44 | H2: =VLOOKUP(D2,Sales_Reps!$A$2:$C$31,3,FALSE) -> North | I2: =DATE(YEAR(B2),MONTH(B2),1) -> 45536 | J2: =Sales_Reps!A2 -> R001 | K2: =SUMIF($D$2:$D$2001,J2,$C$2:$C$2001) -> 789849.6 | L2: =Orders!K2 -> Pune | M2: =Orders!G2 -> 3620 | N2: =IFERROR(VLOOKUP(Orders!D2,Products!$A$2:$D$61,4,FALSE),"") -> 2509 | O2: =IF(OR(N2="",M2<=0),"",(M2-N2)/M2) -> 0.30690608 | P2: =_xlfn.RANK.EQ(K2,$K$2:$K$31,0) -> 23 | Q2: =Orders!D2 -> PROD-014 | R2: =Products!A2 -> PROD-001 | S2: =SUMIFS($C$2:$C$2001,$H$2:$H$2001,"West",$Q$2:$Q$2001,R2) -> 155358.84 | T2: =ROWS($T$2:T2) -> 1 | U2: =VLOOKUP(INDEX($J$2:$J$31,MATCH(T2,$P$2:$P$31,0)),Sales_Reps!$A$2:$B$31,2,FALSE) -> Neha Desai
A3: =Orders!A3 -> ORD-00002 | B3: =Orders!B3 -> 45340 | C3: =Orders!I3 -> 1462.88 | D3: =Orders!E3 -> R005 | E3: =IFERROR(VLOOKUP(Orders!D3,Products!$A$2:$C$61,3,FALSE),"Unknown") -> Apparel | F3: =IFERROR(VLOOKUP(Orders!C3,Customers!$A$2:$E$301,5,FALSE),"Unknown") -> Retail | G3: =IFERROR(VLOOKUP(Orders!C3,Customers!$A$2:$C$301,3,FALSE),"") -> 39 | H3: =VLOOKUP(D3,Sales_Reps!$A$2:$C$31,3,FALSE) -> North | I3: =DATE(YEAR(B3),MONTH(B3),1) -> 45323 | J3: =Sales_Reps!A3 -> R002 | K3: =SUMIF($D$2:$D$2001,J3,$C$2:$C$2001) -> 980063.66 | L3: =Orders!K3 -> Chennai | M3: =Orders!G3 -> 820 | N3: =IFERROR(VLOOKUP(Orders!D3,Products!$A$2:$D$61,4,FALSE),"") -> 391 | O3: =IF(OR(N3="",M3<=0),"",(M3-N3)/M3) -> 0.52317073 | P3: =_xlfn.RANK.EQ(K3,$K$2:$K$31,0) -> 9 | Q3: =Orders!D3 -> PROD-020 | R3: =Products!A3 -> PROD-002 | S3: =SUMIFS($C$2:$C$2001,$H$2:$H$2001,"West",$Q$2:$Q$2001,R3) -> 105284.4 | T3: =ROWS($T$2:T3) -> 2 | U3: =VLOOKUP(INDEX($J$2:$J$31,MATCH(T3,$P$2:$P$31,0)),Sales_Reps!$A$2:$B$31,2,FALSE) -> Shalini Patel
A4: =Orders!A4 -> ORD-00003 | B4: =Orders!B4 -> 45371 | C4: =Orders!I4 -> 3635.92 | D4: =Orders!E4 -> R014 | E4: =IFERROR(VLOOKUP(Orders!D4,Products!$A$2:$C$61,3,FALSE),"Unknown") -> Sports | F4: =IFERROR(VLOOKUP(Orders!C4,Customers!$A$2:$E$301,5,FALSE),"Unknown") -> Retail | G4: =IFERROR(VLOOKUP(Orders!C4,Customers!$A$2:$C$301,3,FALSE),"") -> 52 | H4: =VLOOKUP(D4,Sales_Reps!$A$2:$C$31,3,FALSE) -> South | I4: =DATE(YEAR(B4),MONTH(B4),1) -> 45352 | J4: =Sales_Reps!A4 -> R003 | K4: =SUMIF($D$2:$D$2001,J4,$C$2:$C$2001) -> 986692.91 | L4: =Orders!K4 -> Delhi | M4: =Orders!G4 -> 470 | N4: =IFERROR(VLOOKUP(Orders!D4,Products!$A$2:$D$61,4,FALSE),"") -> 302 | O4: =IF(OR(N4="",M4<=0),"",(M4-N4)/M4) -> 0.35744681 | P4: =_xlfn.RANK.EQ(K4,$K$2:$K$31,0) -> 7 | Q4: =Orders!D4 -> PROD-053 | R4: =Products!A4 -> PROD-003 | S4: =SUMIFS($C$2:$C$2001,$H$2:$H$2001,"West",$Q$2:$Q$2001,R4) -> 248025.75 | T4: =ROWS($T$2:T4) -> 3 | U4: =VLOOKUP(INDEX($J$2:$J$31,MATCH(T4,$P$2:$P$31,0)),Sales_Reps!$A$2:$B$31,2,FALSE) -> Deepak Shah
A5: =Orders!A5 -> ORD-00004 | B5: =Orders!B5 -> 45413 | C5: =Orders!I5 -> 3085.38 | D5: =Orders!E5 -> R006 | E5: =IFERROR(VLOOKUP(Orders!D5,Products!$A$2:$C$61,3,FALSE),"Unknown") -> Grocery | F5: =IFERROR(VLOOKUP(Orders!C5,Customers!$A$2:$E$301,5,FALSE),"Unknown") -> Corporate | G5: =IFERROR(VLOOKUP(Orders!C5,Customers!$A$2:$C$301,3,FALSE),"") -> 46 | H5: =VLOOKUP(D5,Sales_Reps!$A$2:$C$31,3,FALSE) -> North | I5: =DATE(YEAR(B5),MONTH(B5),1) -> 45413 | J5: =Sales_Reps!A5 -> R004 | K5: =SUMIF($D$2:$D$2001,J5,$C$2:$C$2001) -> 589026.29 | L5: =Orders!K5 -> Delhi | M5: =Orders!G5 -> 3660 | N5: =IFERROR(VLOOKUP(Orders!D5,Products!$A$2:$D$61,4,FALSE),"") -> 2214 | O5: =IF(OR(N5="",M5<=0),"",(M5-N5)/M5) -> 0.39508197 | P5: =_xlfn.RANK.EQ(K5,$K$2:$K$31,0) -> 29 | Q5: =Orders!D5 -> PROD-028 | R5: =Products!A5 -> PROD-004 | S5: =SUMIFS($C$2:$C$2001,$H$2:$H$2001,"West",$Q$2:$Q$2001,R5) -> 198124.65 | T5: =ROWS($T$2:T5) -> 4 | U5: =VLOOKUP(INDEX($J$2:$J$31,MATCH(T5,$P$2:$P$31,0)),Sales_Reps!$A$2:$B$31,2,FALSE) -> Nisha Menon
A6: =Orders!A6 -> ORD-00005 | B6: =Orders!B6 -> 45611 | C6: =Orders!I6 -> 2338.4 | D6: =Orders!E6 -> R008 | E6: =IFERROR(VLOOKUP(Orders!D6,Products!$A$2:$C$61,3,FALSE),"Unknown") -> Apparel | F6: =IFERROR(VLOOKUP(Orders!C6,Customers!$A$2:$E$301,5,FALSE),"Unknown") -> Retail | G6: =IFERROR(VLOOKUP(Orders!C6,Customers!$A$2:$C$301,3,FALSE),"") -> 36 | H6: =VLOOKUP(D6,Sales_Reps!$A$2:$C$31,3,FALSE) -> North | I6: =DATE(YEAR(B6),MONTH(B6),1) -> 45597 | J6: =Sales_Reps!A6 -> R005 | K6: =SUMIF($D$2:$D$2001,J6,$C$2:$C$2001) -> 782445.33 | L6: =Orders!K6 -> Chennai | M6: =Orders!G6 -> 3160 | N6: =IFERROR(VLOOKUP(Orders!D6,Products!$A$2:$D$61,4,FALSE),"") -> 1886 | O6: =IF(OR(N6="",M6<=0),"",(M6-N6)/M6) -> 0.40316456 | P6: =_xlfn.RANK.EQ(K6,$K$2:$K$31,0) -> 24 | Q6: =Orders!D6 -> PROD-012 | R6: =Products!A6 -> PROD-005 | S6: =SUMIFS($C$2:$C$2001,$H$2:$H$2001,"West",$Q$2:$Q$2001,R6) -> 7449.9 | T6: =ROWS($T$2:T6) -> 5 | U6: =VLOOKUP(INDEX($J$2:$J$31,MATCH(T6,$P$2:$P$31,0)),Sales_Reps!$A$2:$B$31,2,FALSE) -> Arun Iyer
A7: =Orders!A7 -> ORD-00006 | B7: =Orders!B7 -> 45406 | C7: =Orders!I7 -> 1050.8 | D7: =Orders!E7 -> R025 | E7: =IFERROR(VLOOKUP(Orders!D7,Products!$A$2:$C$61,3,FALSE),"Unknown") -> Home | F7: =IFERROR(VLOOKUP(Orders!C7,Customers!$A$2:$E$301,5,FALSE),"Unknown") -> Retail | G7: =IFERROR(VLOOKUP(Orders!C7,Customers!$A$2:$C$301,3,FALSE),"") -> 36 | H7: =VLOOKUP(D7,Sales_Reps!$A$2:$C$31,3,FALSE) -> West | I7: =DATE(YEAR(B7),MONTH(B7),1) -> 45383 | J7: =Sales_Reps!A7 -> R006 | K7: =SUMIF($D$2:$D$2001,J7,$C$2:$C$2001) -> 1138648.7 | L7: =Orders!K7 -> Mumbai | M7: =Orders!G7 -> 370 | N7: =IFERROR(VLOOKUP(Orders!D7,Products!$A$2:$D$61,4,FALSE),"") -> 288 | O7: =IF(OR(N7="",M7<=0),"",(M7-N7)/M7) -> 0.22162162 | P7: =_xlfn.RANK.EQ(K7,$K$2:$K$31,0) -> 1 | Q7: =Orders!D7 -> PROD-032 | R7: =Products!A7 -> PROD-006 | S7: =SUMIFS($C$2:$C$2001,$H$2:$H$2001,"West",$Q$2:$Q$2001,R7) -> 100869.76
A8: =Orders!A8 -> ORD-00007 | B8: =Orders!B8 -> 45455 | C8: =Orders!I8 -> 2712.96 | D8: =Orders!E8 -> R024 | E8: =IFERROR(VLOOKUP(Orders!D8,Products!$A$2:$C$61,3,FALSE),"Unknown") -> Sports | F8: =IFERROR(VLOOKUP(Orders!C8,Customers!$A$2:$E$301,5,FALSE),"Unknown") -> Retail | G8: =IFERROR(VLOOKUP(Orders!C8,Customers!$A$2:$C$301,3,FALSE),"") -> 27 | H8: =VLOOKUP(D8,Sales_Reps!$A$2:$C$31,3,FALSE) -> West | I8: =DATE(YEAR(B8),MONTH(B8),1) -> 45444 | J8: =Sales_Reps!A8 -> R007 | K8: =SUMIF($D$2:$D$2001,J8,$C$2:$C$2001) -> 855749.68 | L8: =Orders!K8 -> Bengaluru | M8: =Orders!G8 -> 960 | N8: =IFERROR(VLOOKUP(Orders!D8,Products!$A$2:$D$61,4,FALSE),"") -> 705 | O8: =IF(OR(N8="",M8<=0),"",(M8-N8)/M8) -> 0.265625 | P8: =_xlfn.RANK.EQ(K8,$K$2:$K$31,0) -> 19 | Q8: =Orders!D8 -> PROD-057 | R8: =Products!A8 -> PROD-007 | S8: =SUMIFS($C$2:$C$2001,$H$2:$H$2001,"West",$Q$2:$Q$2001,R8) -> 38531.35
A9: =Orders!A9 -> ORD-00008 | B9: =Orders!B9 -> 45617 | C9: =Orders!I9 -> 11165.44 | D9: =Orders!E9 -> R019 | E9: =IFERROR(VLOOKUP(Orders!D9,Products!$A$2:$C$61,3,FALSE),"Unknown") -> Electronics | F9: =IFERROR(VLOOKUP(Orders!C9,Customers!$A$2:$E$301,5,FALSE),"Unknown") -> Corporate | G9: =IFERROR(VLOOKUP(Orders!C9,Customers!$A$2:$C$301,3,FALSE),"") -> 57 | H9: =VLOOKUP(D9,Sales_Reps!$A$2:$C$31,3,FALSE) -> East | I9: =DATE(YEAR(B9),MONTH(B9),1) -> 45597 | J9: =Sales_Reps!A9 -> R008 | K9: =SUMIF($D$2:$D$2001,J9,$C$2:$C$2001) -> 861553.33 | L9: =Orders!K9 -> Bengaluru | M9: =Orders!G9 -> 1430 | N9: =IFERROR(VLOOKUP(Orders!D9,Products!$A$2:$D$61,4,FALSE),"") -> 861 | O9: =IF(OR(N9="",M9<=0),"",(M9-N9)/M9) -> 0.3979021 | P9: =_xlfn.RANK.EQ(K9,$K$2:$K$31,0) -> 18 | Q9: =Orders!D9 -> PROD-007 | R9: =Products!A9 -> PROD-008 | S9: =SUMIFS($C$2:$C$2001,$H$2:$H$2001,"West",$Q$2:$Q$2001,R9) -> 7807.1
A10: =Orders!A10 -> ORD-00009 | B10: =Orders!B10 -> 45549 | C10: =Orders!I10 -> 14131.26 | D10: =Orders!E10 -> R008 | E10: =IFERROR(VLOOKUP(Orders!D10,Products!$A$2:$C$61,3,FALSE),"Unknown") -> Home | F10: =IFERROR(VLOOKUP(Orders!C10,Customers!$A$2:$E$301,5,FALSE),"Unknown") -> Retail | G10: =IFERROR(VLOOKUP(Orders!C10,Customers!$A$2:$C$301,3,FALSE),"") -> 42 | H10: =VLOOKUP(D10,Sales_Reps!$A$2:$C$31,3,FALSE) -> North | I10: =DATE(YEAR(B10),MONTH(B10),1) -> 45536 | J10: =Sales_Reps!A10 -> R009 | K10: =SUMIF($D$2:$D$2001,J10,$C$2:$C$2001) -> 914554.72 | L10: =Orders!K10 -> Bengaluru | M10: =Orders!G10 -> 5490 | N10: =IFERROR(VLOOKUP(Orders!D10,Products!$A$2:$D$61,4,FALSE),"") -> 2549 | O10: =IF(OR(N10="",M10<=0),"",(M10-N10)/M10) -> 0.53570128 | P10: =_xlfn.RANK.EQ(K10,$K$2:$K$31,0) -> 12 | Q10: =Orders!D10 -> PROD-038 | R10: =Products!A10 -> PROD-009 | S10: =SUMIFS($C$2:$C$2001,$H$2:$H$2001,"West",$Q$2:$Q$2001,R10) -> 64207.38
A11: =Orders!A11 -> ORD-00010 | B11: =Orders!B11 -> 45396 | C11: =Orders!I11 -> 2875.08 | D11: =Orders!E11 -> R028 | E11: =IFERROR(VLOOKUP(Orders!D11,Products!$A$2:$C$61,3,FALSE),"Unknown") -> Grocery | F11: =IFERROR(VLOOKUP(Orders!C11,Customers!$A$2:$E$301,5,FALSE),"Unknown") -> Retail | G11: =IFERROR(VLOOKUP(Orders!C11,Customers!$A$2:$C$301,3,FALSE),"") -> 56 | H11: =VLOOKUP(D11,Sales_Reps!$A$2:$C$31,3,FALSE) -> West | I11: =DATE(YEAR(B11),MONTH(B11),1) -> 45383 | J11: =Sales_Reps!A11 -> R010 | K11: =SUMIF($D$2:$D$2001,J11,$C$2:$C$2001) -> 880345.2 | L11: =Orders!K11 -> Pune | M11: =Orders!G11 -> 970 | N11: =IFERROR(VLOOKUP(Orders!D11,Products!$A$2:$D$61,4,FALSE),"") -> 434 | O11: =IF(OR(N11="",M11<=0),"",(M11-N11)/M11) -> 0.55257732 | P11: =_xlfn.RANK.EQ(K11,$K$2:$K$31,0) -> 17 | Q11: =Orders!D11 -> PROD-030 | R11: =Products!A11 -> PROD-010 | S11: =SUMIFS($C$2:$C$2001,$H$2:$H$2001,"West",$Q$2:$Q$2001,R11) -> 67393.92
A12: =Orders!A12 -> ORD-00011 | B12: =Orders!B12 -> 45560 | C12: =Orders!I12 -> 14761.81 | D12: =Orders!E12 -> R010 | E12: =IFERROR(VLOOKUP(Orders!D12,Products!$A$2:$C$61,3,FALSE),"Unknown") -> Grocery | F12: =IFERROR(VLOOKUP(Orders!C12,Customers!$A$2:$E$301,5,FALSE),"Unknown") -> Retail | G12: =IFERROR(VLOOKUP(Orders!C12,Customers!$A$2:$C$301,3,FALSE),"") -> 60 | H12: =VLOOKUP(D12,Sales_Reps!$A$2:$C$31,3,FALSE) -> South | I12: =DATE(YEAR(B12),MONTH(B12),1) -> 45536 | J12: =Sales_Reps!A12 -> R011 | K12: =SUMIF($D$2:$D$2001,J12,$C$2:$C$2001) -> 735207.76 | L12: =Orders!K12 -> Hyderabad | M12: =Orders!G12 -> 2270 | N12: =IFERROR(VLOOKUP(Orders!D12,Products!$A$2:$D$61,4,FALSE),"") -> 1203 | O12: =IF(OR(N12="",M12<=0),"",(M12-N12)/M12) -> 0.47004405 | P12: =_xlfn.RANK.EQ(K12,$K$2:$K$31,0) -> 28 | Q12: =Orders!D12 -> PROD-024 | R12: =Products!A12 -> PROD-011 | S12: =SUMIFS($C$2:$C$2001,$H$2:$H$2001,"West",$Q$2:$Q$2001,R12) -> 145224.3
A13: =Orders!A13 -> ORD-00012 | B13: =Orders!B13 -> 45332 | C13: =Orders!I13 -> 18604.08 | D13: =Orders!E13 -> R024 | E13: =IFERROR(VLOOKUP(Orders!D13,Products!$A$2:$C$61,3,FALSE),"Unknown") -> Electronics | F13: =IFERROR(VLOOKUP(Orders!C13,Customers!$A$2:$E$301,5,FALSE),"Unknown") -> Retail | G13: =IFERROR(VLOOKUP(Orders!C13,Customers!$A$2:$C$301,3,FALSE),"") -> 56 | H13: =VLOOKUP(D13,Sales_Reps!$A$2:$C$31,3,FALSE) -> West | I13: =DATE(YEAR(B13),MONTH(B13),1) -> 45323 | J13: =Sales_Reps!A13 -> R012 | K13: =SUMIF($D$2:$D$2001,J13,$C$2:$C$2001) -> 901394.32 | L13: =Orders!K13 -> Pune | M13: =Orders!G13 -> 2640 | N13: =IFERROR(VLOOKUP(Orders!D13,Products!$A$2:$D$61,4,FALSE),"") -> 1149 | O13: =IF(OR(N13="",M13<=0),"",(M13-N13)/M13) -> 0.56477273 | P13: =_xlfn.RANK.EQ(K13,$K$2:$K$31,0) -> 14 | Q13: =Orders!D13 -> PROD-010 | R13: =Products!A13 -> PROD-012 | S13: =SUMIFS($C$2:$C$2001,$H$2:$H$2001,"West",$Q$2:$Q$2001,R13) -> 121770.6
A14: =Orders!A14 -> ORD-00013 | B14: =Orders!B14 -> 45507 | C14: =Orders!I14 -> 7464.6 | D14: =Orders!E14 -> R004 | E14: =IFERROR(VLOOKUP(Orders!D14,Products!$A$2:$C$61,3,FALSE),"Unknown") -> Electronics | F14: =IFERROR(VLOOKUP(Orders!C14,Customers!$A$2:$E$301,5,FALSE),"Unknown") -> SMB | G14: =IFERROR(VLOOKUP(Orders!C14,Customers!$A$2:$C$301,3,FALSE),"") -> 27 | H14: =VLOOKUP(D14,Sales_Reps!$A$2:$C$31,3,FALSE) -> North | I14: =DATE(YEAR(B14),MONTH(B14),1) -> 45505 | J14: =Sales_Reps!A14 -> R013 | K14: =SUMIF($D$2:$D$2001,J14,$C$2:$C$2001) -> 811524.38 | L14: =Orders!K14 -> Delhi | M14: =Orders!G14 -> 2600 | N14: =IFERROR(VLOOKUP(Orders!D14,Products!$A$2:$D$61,4,FALSE),"") -> 1052 | O14: =IF(OR(N14="",M14<=0),"",(M14-N14)/M14) -> 0.59538462 | P14: =_xlfn.RANK.EQ(K14,$K$2:$K$31,0) -> 22 | Q14: =Orders!D14 -> PROD-002 | R14: =Products!A14 -> PROD-013 | S14: =SUMIFS($C$2:$C$2001,$H$2:$H$2001,"West",$Q$2:$Q$2001,R14) -> 85543.64
A15: =Orders!A15 -> ORD-00014 | B15: =Orders!B15 -> 45466 | C15: =Orders!I15 -> 8375.25 | D15: =Orders!E15 -> R025 | E15: =IFERROR(VLOOKUP(Orders!D15,Products!$A$2:$C$61,3,FALSE),"Unknown") -> Home | F15: =IFERROR(VLOOKUP(Orders!C15,Customers!$A$2:$E$301,5,FALSE),"Unknown") -> SMB | G15: =IFERROR(VLOOKUP(Orders!C15,Customers!$A$2:$C$301,3,FALSE),"") -> 39 | H15: =VLOOKUP(D15,Sales_Reps!$A$2:$C$31,3,FALSE) -> West | I15: =DATE(YEAR(B15),MONTH(B15),1) -> 45444 | J15: =Sales_Reps!A15 -> R014 | K15: =SUMIF($D$2:$D$2001,J15,$C$2:$C$2001) -> 995713.54 | L15: =Orders!K15 -> Pune | M15: =Orders!G15 -> 3250 | N15: =IFERROR(VLOOKUP(Orders!D15,Products!$A$2:$D$61,4,FALSE),"") -> 1556 | O15: =IF(OR(N15="",M15<=0),"",(M15-N15)/M15) -> 0.52123077 | P15: =_xlfn.RANK.EQ(K15,$K$2:$K$31,0) -> 6 | Q15: =Orders!D15 -> PROD-036 | R15: =Products!A15 -> PROD-014 | S15: =SUMIFS($C$2:$C$2001,$H$2:$H$2001,"West",$Q$2:$Q$2001,R15) -> 95390.62
A16: =Orders!A16 -> ORD-00015 | B16: =Orders!B16 -> 45365 | C16: =Orders!I16 -> 150.67 | D16: =Orders!E16 -> R003 | E16: =IFERROR(VLOOKUP(Orders!D16,Products!$A$2:$C$61,3,FALSE),"Unknown") -> Sports | F16: =IFERROR(VLOOKUP(Orders!C16,Customers!$A$2:$E$301,5,FALSE),"Unknown") -> Retail | G16: =IFERROR(VLOOKUP(Orders!C16,Customers!$A$2:$C$301,3,FALSE),"") -> 38 | H16: =VLOOKUP(D16,Sales_Reps!$A$2:$C$31,3,FALSE) -> North | I16: =DATE(YEAR(B16),MONTH(B16),1) -> 45352 | J16: =Sales_Reps!A16 -> R015 | K16: =SUMIF($D$2:$D$2001,J16,$C$2:$C$2001) -> 1091740.2 | L16: =Orders!K16 -> Pune | M16: =Orders!G16 -> 190 | N16: =IFERROR(VLOOKUP(Orders!D16,Products!$A$2:$D$61,4,FALSE),"") -> 147 | O16: =IF(OR(N16="",M16<=0),"",(M16-N16)/M16) -> 0.22631579 | P16: =_xlfn.RANK.EQ(K16,$K$2:$K$31,0) -> 3 | Q16: =Orders!D16 -> PROD-060 | R16: =Products!A16 -> PROD-015 | S16: =SUMIFS($C$2:$C$2001,$H$2:$H$2001,"West",$Q$2:$Q$2001,R16) -> 108190.72
A17: =Orders!A17 -> ORD-00016 | B17: =Orders!B17 -> 45546 | C17: =Orders!I17 -> 15086.4 | D17: =Orders!E17 -> R014 | E17: =IFERROR(VLOOKUP(Orders!D17,Products!$A$2:$C$61,3,FALSE),"Unknown") -> Sports | F17: =IFERROR(VLOOKUP(Orders!C17,Customers!$A$2:$E$301,5,FALSE),"Unknown") -> Retail | G17: =IFERROR(VLOOKUP(Orders!C17,Customers!$A$2:$C$301,3,FALSE),"") -> 63 | H17: =VLOOKUP(D17,Sales_Reps!$A$2:$C$31,3,FALSE) -> South | I17: =DATE(YEAR(B17),MONTH(B17),1) -> 45536 | J17: =Sales_Reps!A17 -> R016 | K17: =SUMIF($D$2:$D$2001,J17,$C$2:$C$2001) -> 814563.71 | L17: =Orders!K17 -> Pune | M17: =Orders!G17 -> 2400 | N17: =IFERROR(VLOOKUP(Orders!D17,Products!$A$2:$D$61,4,FALSE),"") -> 974 | O17: =IF(OR(N17="",M17<=0),"",(M17-N17)/M17) -> 0.59416667 | P17: =_xlfn.RANK.EQ(K17,$K$2:$K$31,0) -> 21 | Q17: =Orders!D17 -> PROD-058 | R17: =Products!A17 -> PROD-016 | S17: =SUMIFS($C$2:$C$2001,$H$2:$H$2001,"West",$Q$2:$Q$2001,R17) -> 12964.82
A18: =Orders!A18 -> ORD-00017 | B18: =Orders!B18 -> 45512 | C18: =Orders!I18 -> 14259.36 | D18: =Orders!E18 -> R023 | E18: =IFERROR(VLOOKUP(Orders!D18,Products!$A$2:$C$61,3,FALSE),"Unknown") -> Grocery | F18: =IFERROR(VLOOKUP(Orders!C18,Customers!$A$2:$E$301,5,FALSE),"Unknown") -> SMB | G18: =IFERROR(VLOOKUP(Orders!C18,Customers!$A$2:$C$301,3,FALSE),"") -> 46 | H18: =VLOOKUP(D18,Sales_Reps!$A$2:$C$31,3,FALSE) -> East | I18: =DATE(YEAR(B18),MONTH(B18),1) -> 45505 | J18: =Sales_Reps!A18 -> R017 | K18: =SUMIF($D$2:$D$2001,J18,$C$2:$C$2001) -> 780384.41 | L18: =Orders!K18 -> Bengaluru | M18: =Orders!G18 -> 3660 | N18: =IFERROR(VLOOKUP(Orders!D18,Products!$A$2:$D$61,4,FALSE),"") -> 2214 | O18: =IF(OR(N18="",M18<=0),"",(M18-N18)/M18) -> 0.39508197 | P18: =_xlfn.RANK.EQ(K18,$K$2:$K$31,0) -> 25 | Q18: =Orders!D18 -> PROD-028 | R18: =Products!A18 -> PROD-017 | S18: =SUMIFS($C$2:$C$2001,$H$2:$H$2001,"West",$Q$2:$Q$2001,R18) -> 84699.95
... A31: =Orders!A31 -> ORD-00030 | B31: =Orders!B31 -> 45367 | C31: =Orders!I31 -> 6366.36 | D31: =Orders!E31 -> R005 | E31: =IFERROR(VLOOKUP(Orders!D31,Products!$A$2:$C$61,3,FALSE),"Unknown") -> Sports | F31: =IFERROR(VLOOKUP(Orders!C31,Customers!$A$2:$E$301,5,FALSE),"Unknown") -> SMB | G31: =IFERROR(VLOOKUP(Orders!C31,Customers!$A$2:$C$301,3,FALSE),"") -> 44 | H31: =VLOOKUP(D31,Sales_Reps!$A$2:$C$31,3,FALSE) -> North | I31: =DATE(YEAR(B31),MONTH(B31),1) -> 45352 | J31: =Sales_Reps!A31 -> R030 | K31: =SUMIF($D$2:$D$2001,J31,$C$2:$C$2001) -> 747624.37 | L31: =Orders!K31 -> Pune | M31: =Orders!G31 -> 2860 | N31: =IFERROR(VLOOKUP(Orders!D31,Products!$A$2:$D$61,4,FALSE),"") -> 2028 | O31: =IF(OR(N31="",M31<=0),"",(M31-N31)/M31) -> 0.29090909 | P31: =_xlfn.RANK.EQ(K31,$K$2:$K$31,0) -> 27 | Q31: =Orders!D31 -> PROD-055 | R31: =Products!A31 -> PROD-030 | S31: =SUMIFS($C$2:$C$2001,$H$2:$H$2001,"West",$Q$2:$Q$2001,R31) -> 37405.14
A32: =Orders!A32 -> ORD-00031 | B32: =Orders!B32 -> 45569 | C32: =Orders!I32 -> 4766.58 | D32: =Orders!E32 -> R006 | E32: =IFERROR(VLOOKUP(Orders!D32,Products!$A$2:$C$61,3,FALSE),"Unknown") -> Grocery | F32: =IFERROR(VLOOKUP(Orders!C32,Customers!$A$2:$E$301,5,FALSE),"Unknown") -> Corporate | G32: =IFERROR(VLOOKUP(Orders!C32,Customers!$A$2:$C$301,3,FALSE),"") -> 47 | H32: =VLOOKUP(D32,Sales_Reps!$A$2:$C$31,3,FALSE) -> North | I32: =DATE(YEAR(B32),MONTH(B32),1) -> 45566 | L32: =Orders!K32 -> Pune | M32: =Orders!G32 -> 970 | N32: =IFERROR(VLOOKUP(Orders!D32,Products!$A$2:$D$61,4,FALSE),"") -> 434 | O32: =IF(OR(N32="",M32<=0),"",(M32-N32)/M32) -> 0.55257732 | Q32: =Orders!D32 -> PROD-030 | R32: =Products!A32 -> PROD-031 | S32: =SUMIFS($C$2:$C$2001,$H$2:$H$2001,"West",$Q$2:$Q$2001,R32) -> 102321.36
A33: =Orders!A33 -> ORD-00032 | B33: =Orders!B33 -> 45641 | C33: =Orders!I33 -> 10388.64 | D33: =Orders!E33 -> R026 | E33: =IFERROR(VLOOKUP(Orders!D33,Products!$A$2:$C$61,3,FALSE),"Unknown") -> Grocery | F33: =IFERROR(VLOOKUP(Orders!C33,Customers!$A$2:$E$301,5,FALSE),"Unknown") -> Retail | G33: =IFERROR(VLOOKUP(Orders!C33,Customers!$A$2:$C$301,3,FALSE),"") -> 53 | H33: =VLOOKUP(D33,Sales_Reps!$A$2:$C$31,3,FALSE) -> West | I33: =DATE(YEAR(B33),MONTH(B33),1) -> 45627 | L33: =Orders!K33 -> Hyderabad | M33: =Orders!G33 -> 2760 | N33: =IFERROR(VLOOKUP(Orders!D33,Products!$A$2:$D$61,4,FALSE),"") -> 1435 | O33: =IF(OR(N33="",M33<=0),"",(M33-N33)/M33) -> 0.48007246 | Q33: =Orders!D33 -> PROD-021 | R33: =Products!A33 -> PROD-032 | S33: =SUMIFS($C$2:$C$2001,$H$2:$H$2001,"West",$Q$2:$Q$2001,R33) -> 20402.17
A34: =Orders!A34 -> ORD-00033 | B34: =Orders!B34 -> 45343 | C34: =Orders!I34 -> 5392.2 | D34: =Orders!E34 -> R009 | E34: =IFERROR(VLOOKUP(Orders!D34,Products!$A$2:$C$61,3,FALSE),"Unknown") -> Home | F34: =IFERROR(VLOOKUP(Orders!C34,Customers!$A$2:$E$301,5,FALSE),"Unknown") -> Corporate | G34: =IFERROR(VLOOKUP(Orders!C34,Customers!$A$2:$C$301,3,FALSE),"") -> 32 | H34: =VLOOKUP(D34,Sales_Reps!$A$2:$C$31,3,FALSE) -> South | I34: =DATE(YEAR(B34),MONTH(B34),1) -> 45323 | J34: R015 November Actual | K34: =SUMIFS($C$2:$C$2001,$D$2:$D$2001,"R015",$B$2:$B$2001,">="&DATE(2024,11,1),$B$2:$B$2001,"<"&DATE(2024,12,1)) -> 97394.65 | L34: =Orders!K34 -> Hyderabad | M34: =Orders!G34 -> 660 | N34: =IFERROR(VLOOKUP(Orders!D34,Products!$A$2:$D$61,4,FALSE),"") -> 329 | O34: =IF(OR(N34="",M34<=0),"",(M34-N34)/M34) -> 0.50151515 | Q34: =Orders!D34 -> PROD-037 | R34: =Products!A34 -> PROD-033 | S34: =SUMIFS($C$2:$C$2001,$H$2:$H$2001,"West",$Q$2:$Q$2001,R34) -> 137585.28
A35: =Orders!A35 -> ORD-00034 | B35: =Orders!B35 -> 45576 | C35: =Orders!I35 -> 2902.25 | D35: =Orders!E35 -> R019 | E35: =IFERROR(VLOOKUP(Orders!D35,Products!$A$2:$C$61,3,FALSE),"Unknown") -> Home | F35: =IFERROR(VLOOKUP(Orders!C35,Customers!$A$2:$E$301,5,FALSE),"Unknown") -> SMB | G35: =IFERROR(VLOOKUP(Orders!C35,Customers!$A$2:$C$301,3,FALSE),"") -> 40 | H35: =VLOOKUP(D35,Sales_Reps!$A$2:$C$31,3,FALSE) -> East | I35: =DATE(YEAR(B35),MONTH(B35),1) -> 45566 | J35: R015 November Target | K35: =INDEX(Targets!$B$2:$M$31,MATCH("R015",Targets!$A$2:$A$31,0),MATCH("Nov-24",Targets!$B$1:$M$1,0)) -> 418857 | L35: =Orders!K35 -> Hyderabad | M35: =Orders!G35 -> 3250 | N35: =IFERROR(VLOOKUP(Orders!D35,Products!$A$2:$D$61,4,FALSE),"") -> 1556 | O35: =IF(OR(N35="",M35<=0),"",(M35-N35)/M35) -> 0.52123077 | Q35: =Orders!D35 -> PROD-036 | R35: =Products!A35 -> PROD-034 | S35: =SUMIFS($C$2:$C$2001,$H$2:$H$2001,"West",$Q$2:$Q$2001,R35) -> 221112.08
A36: =Orders!A36 -> ORD-00035 | B36: =Orders!B36 -> 45462 | C36: =Orders!I36 -> 30028.8 | D36: =Orders!E36 -> R019 | E36: =IFERROR(VLOOKUP(Orders!D36,Products!$A$2:$C$61,3,FALSE),"Unknown") -> Beauty | F36: =IFERROR(VLOOKUP(Orders!C36,Customers!$A$2:$E$301,5,FALSE),"Unknown") -> Retail | G36: =IFERROR(VLOOKUP(Orders!C36,Customers!$A$2:$C$301,3,FALSE),"") -> 26 | H36: =VLOOKUP(D36,Sales_Reps!$A$2:$C$31,3,FALSE) -> East | I36: =DATE(YEAR(B36),MONTH(B36),1) -> 45444 | L36: =Orders!K36 -> Hyderabad | M36: =Orders!G36 -> 5100 | N36: =IFERROR(VLOOKUP(Orders!D36,Products!$A$2:$D$61,4,FALSE),"") -> 2237 | O36: =IF(OR(N36="",M36<=0),"",(M36-N36)/M36) -> 0.56137255 | Q36: =Orders!D36 -> PROD-048 | R36: =Products!A36 -> PROD-035 | S36: =SUMIFS($C$2:$C$2001,$H$2:$H$2001,"West",$Q$2:$Q$2001,R36) -> 26929.54
A37: =Orders!A37 -> ORD-00036 | B37: =Orders!B37 -> 45442 | C37: =Orders!I37 -> 1024.92 | D37: =Orders!E37 -> R021 | E37: =IFERROR(VLOOKUP(Orders!D37,Products!$A$2:$C$61,3,FALSE),"Unknown") -> Home | F37: =IFERROR(VLOOKUP(Orders!C37,Customers!$A$2:$E$301,5,FALSE),"Unknown") -> Retail | G37: =IFERROR(VLOOKUP(Orders!C37,Customers!$A$2:$C$301,3,FALSE),"") -> 41 | H37: =VLOOKUP(D37,Sales_Reps!$A$2:$C$31,3,FALSE) -> East | I37: =DATE(YEAR(B37),MONTH(B37),1) -> 45413 | L37: =Orders!K37 -> Delhi | M37: =Orders!G37 -> 1080 | N37: =IFERROR(VLOOKUP(Orders!D37,Products!$A$2:$D$61,4,FALSE),"") -> 519 | O37: =IF(OR(N37="",M37<=0),"",(M37-N37)/M37) -> 0.51944444 | Q37: =Orders!D37 -> PROD-040 | R37: =Products!A37 -> PROD-036 | S37: =SUMIFS($C$2:$C$2001,$H$2:$H$2001,"West",$Q$2:$Q$2001,R37) -> 88426
A38: =Orders!A38 -> ORD-00037 | B38: =Orders!B38 -> 45646 | C38: =Orders!I38 -> 8663.22 | D38: =Orders!E38 -> R009 | E38: =IFERROR(VLOOKUP(Orders!D38,Products!$A$2:$C$61,3,FALSE),"Unknown") -> Home | F38: =IFERROR(VLOOKUP(Orders!C38,Customers!$A$2:$E$301,5,FALSE),"Unknown") -> SMB | G38: =IFERROR(VLOOKUP(Orders!C38,Customers!$A$2:$C$301,3,FALSE),"") -> 36 | H38: =VLOOKUP(D38,Sales_Reps!$A$2:$C$31,3,FALSE) -> South | I38: =DATE(YEAR(B38),MONTH(B38),1) -> 45627 | L38: =Orders!K38 -> Mumbai | M38: =Orders!G38 -> 5490 | N38: =IFERROR(VLOOKUP(Orders!D38,Products!$A$2:$D$61,4,FALSE),"") -> 2549 | O38: =IF(OR(N38="",M38<=0),"",(M38-N38)/M38) -> 0.53570128 | Q38: =Orders!D38 -> PROD-038 | R38: =Products!A38 -> PROD-037 | S38: =SUMIFS($C$2:$C$2001,$H$2:$H$2001,"West",$Q$2:$Q$2001,R38) -> 13841.52
A39: =Orders!A39 -> ORD-00038 | B39: =Orders!B39 -> 45478 | C39: =Orders!I39 -> 948.29 | D39: =Orders!E39 -> R001 | E39: =IFERROR(VLOOKUP(Orders!D39,Products!$A$2:$C$61,3,FALSE),"Unknown") -> Sports | F39: =IFERROR(VLOOKUP(Orders!C39,Customers!$A$2:$E$301,5,FALSE),"Unknown") -> Retail | G39: =IFERROR(VLOOKUP(Orders!C39,Customers!$A$2:$C$301,3,FALSE),"") -> 42 | H39: =VLOOKUP(D39,Sales_Reps!$A$2:$C$31,3,FALSE) -> North | I39: =DATE(YEAR(B39),MONTH(B39),1) -> 45474 | L39: =Orders!K39 -> Bengaluru | M39: =Orders!G39 -> 190 | N39: =IFERROR(VLOOKUP(Orders!D39,Products!$A$2:$D$61,4,FALSE),"") -> 147 | O39: =IF(OR(N39="",M39<=0),"",(M39-N39)/M39) -> 0.22631579 | Q39: =Orders!D39 -> PROD-060 | R39: =Products!A39 -> PROD-038 | S39: =SUMIFS($C$2:$C$2001,$H$2:$H$2001,"West",$Q$2:$Q$2001,R39) -> 119445.93
A40: =Orders!A40 -> ORD-00039 | B40: =Orders!B40 -> 45355 | C40: =Orders!I40 -> 14011.2 | D40: =Orders!E40 -> R015 | E40: =IFERROR(VLOOKUP(Orders!D40,Products!$A$2:$C$61,3,FALSE),"Unknown") -> Sports | F40: =IFERROR(VLOOKUP(Orders!C40,Customers!$A$2:$E$301,5,FALSE),"Unknown") -> Retail | G40: =IFERROR(VLOOKUP(Orders!C40,Customers!$A$2:$C$301,3,FALSE),"") -> 51 | H40: =VLOOKUP(D40,Sales_Reps!$A$2:$C$31,3,FALSE) -> South | I40: =DATE(YEAR(B40),MONTH(B40),1) -> 45352 | L40: =Orders!K40 -> Chennai | M40: =Orders!G40 -> 2400 | N40: =IFERROR(VLOOKUP(Orders!D40,Products!$A$2:$D$61,4,FALSE),"") -> 974 | O40: =IF(OR(N40="",M40<=0),"",(M40-N40)/M40) -> 0.59416667 | Q40: =Orders!D40 -> PROD-058 | R40: =Products!A40 -> PROD-039 | S40: =SUMIFS($C$2:$C$2001,$H$2:$H$2001,"West",$Q$2:$Q$2001,R40) -> 177512.66
A41: =Orders!A41 -> ORD-00040 | B41: =Orders!B41 -> 45599 | C41: =Orders!I41 -> 13127.4 | D41: =Orders!E41 -> R023 | E41: =IFERROR(VLOOKUP(Orders!D41,Products!$A$2:$C$61,3,FALSE),"Unknown") -> Beauty | F41: =IFERROR(VLOOKUP(Orders!C41,Customers!$A$2:$E$301,5,FALSE),"Unknown") -> SMB | G41: =IFERROR(VLOOKUP(Orders!C41,Customers!$A$2:$C$301,3,FALSE),"") -> 50 | H41: =VLOOKUP(D41,Sales_Reps!$A$2:$C$31,3,FALSE) -> East | I41: =DATE(YEAR(B41),MONTH(B41),1) -> 45597 | L41: =Orders!K41 -> Delhi | M41: =Orders!G41 -> 1650 | N41: =IFERROR(VLOOKUP(Orders!D41,Products!$A$2:$D$61,4,FALSE),"") -> 1222 | O41: =IF(OR(N41="",M41<=0),"",(M41-N41)/M41) -> 0.25939394 | Q41: =Orders!D41 -> PROD-044 | R41: =Products!A41 -> PROD-040 | S41: =SUMIFS($C$2:$C$2001,$H$2:$H$2001,"West",$Q$2:$Q$2001,R41) -> 47831.04
A42: =Orders!A42 -> ORD-00041 | B42: =Orders!B42 -> 45606 | C42: =Orders!I42 -> 19149.12 | D42: =Orders!E42 -> R006 | E42: =IFERROR(VLOOKUP(Orders!D42,Products!$A$2:$C$61,3,FALSE),"Unknown") -> Home | F42: =IFERROR(VLOOKUP(Orders!C42,Customers!$A$2:$E$301,5,FALSE),"Unknown") -> Unknown | G42: =IFERROR(VLOOKUP(Orders!C42,Customers!$A$2:$C$301,3,FALSE),"") | H42: =VLOOKUP(D42,Sales_Reps!$A$2:$C$31,3,FALSE) -> North | I42: =DATE(YEAR(B42),MONTH(B42),1) -> 45597 | L42: =Orders!K42 -> Chennai | M42: =Orders!G42 -> 5490 | N42: =IFERROR(VLOOKUP(Orders!D42,Products!$A$2:$D$61,4,FALSE),"") -> 2549 | O42: =IF(OR(N42="",M42<=0),"",(M42-N42)/M42) -> 0.53570128 | Q42: =Orders!D42 -> PROD-038 | R42: =Products!A42 -> PROD-041 | S42: =SUMIFS($C$2:$C$2001,$H$2:$H$2001,"West",$Q$2:$Q$2001,R42) -> 80488.1
A43: =Orders!A43 -> ORD-00042 | B43: =Orders!B43 -> 45432 | C43: =Orders!I43 -> 42602.4 | D43: =Orders!E43 -> R014 | E43: =IFERROR(VLOOKUP(Orders!D43,Products!$A$2:$C$61,3,FALSE),"Unknown") -> Beauty | F43: =IFERROR(VLOOKUP(Orders!C43,Customers!$A$2:$E$301,5,FALSE),"Unknown") -> Retail | G43: =IFERROR(VLOOKUP(Orders!C43,Customers!$A$2:$C$301,3,FALSE),"") -> 53 | H43: =VLOOKUP(D43,Sales_Reps!$A$2:$C$31,3,FALSE) -> South | I43: =DATE(YEAR(B43),MONTH(B43),1) -> 45413 | L43: =Orders!K43 -> Delhi | M43: =Orders!G43 -> 4880 | N43: =IFERROR(VLOOKUP(Orders!D43,Products!$A$2:$D$61,4,FALSE),"") -> 2768 | O43: =IF(OR(N43="",M43<=0),"",(M43-N43)/M43) -> 0.43278689 | Q43: =Orders!D43 -> PROD-046 | R43: =Products!A43 -> PROD-042 | S43: =SUMIFS($C$2:$C$2001,$H$2:$H$2001,"West",$Q$2:$Q$2001,R43) -> 138799.19
A44: =Orders!A44 -> ORD-00043 | B44: =Orders!B44 -> 45392 | C44: =Orders!I44 -> 5535.32 | D44: =Orders!E44 -> R019 | E44: =IFERROR(VLOOKUP(Orders!D44,Products!$A$2:$C$61,3,FALSE),"Unknown") -> Home | F44: =IFERROR(VLOOKUP(Orders!C44,Customers!$A$2:$E$301,5,FALSE),"Unknown") -> Retail | G44: =IFERROR(VLOOKUP(Orders!C44,Customers!$A$2:$C$301,3,FALSE),"") -> 37 | H44: =VLOOKUP(D44,Sales_Reps!$A$2:$C$31,3,FALSE) -> East | I44: =DATE(YEAR(B44),MONTH(B44),1) -> 45383 | L44: =Orders!K44 -> Chennai | M44: =Orders!G44 -> 3730 | N44: =IFERROR(VLOOKUP(Orders!D44,Products!$A$2:$D$61,4,FALSE),"") -> 2135 | O44: =IF(OR(N44="",M44<=0),"",(M44-N44)/M44) -> 0.42761394 | Q44: =Orders!D44 -> PROD-031 | R44: =Products!A44 -> PROD-043 | S44: =SUMIFS($C$2:$C$2001,$H$2:$H$2001,"West",$Q$2:$Q$2001,R44) -> 104386
A45: =Orders!A45 -> ORD-00044 | B45: =Orders!B45 -> 45396 | C45: =Orders!I45 -> 10943.4 | D45: =Orders!E45 -> R029 | E45: =IFERROR(VLOOKUP(Orders!D45,Products!$A$2:$C$61,3,FALSE),"Unknown") -> Beauty | F45: =IFERROR(VLOOKUP(Orders!C45,Customers!$A$2:$E$301,5,FALSE),"Unknown") -> SMB | G45: =IFERROR(VLOOKUP(Orders!C45,Customers!$A$2:$C$301,3,FALSE),"") -> 54 | H45: =VLOOKUP(D45,Sales_Reps!$A$2:$C$31,3,FALSE) -> West | I45: =DATE(YEAR(B45),MONTH(B45),1) -> 45383 | L45: =Orders!K45 -> Mumbai | M45: =Orders!G45 -> 3450 | N45: =IFERROR(VLOOKUP(Orders!D45,Products!$A$2:$D$61,4,FALSE),"") -> 2420 | O45: =IF(OR(N45="",M45<=0),"",(M45-N45)/M45) -> 0.29855072 | Q45: =Orders!D45 -> PROD-047 | R45: =Products!A45 -> PROD-044 | S45: =SUMIFS($C$2:$C$2001,$H$2:$H$2001,"West",$Q$2:$Q$2001,R45) -> 68328.15
A46: =Orders!A46 -> ORD-00045 | B46: =Orders!B46 -> 45373 | C46: =Orders!I46 -> 4101.92 | D46: =Orders!E46 -> R019 | E46: =IFERROR(VLOOKUP(Orders!D46,Products!$A$2:$C$61,3,FALSE),"Unknown") -> Apparel | F46: =IFERROR(VLOOKUP(Orders!C46,Customers!$A$2:$E$301,5,FALSE),"Unknown") -> SMB | G46: =IFERROR(VLOOKUP(Orders!C46,Customers!$A$2:$C$301,3,FALSE),"") -> 64 | H46: =VLOOKUP(D46,Sales_Reps!$A$2:$C$31,3,FALSE) -> East | I46: =DATE(YEAR(B46),MONTH(B46),1) -> 45352 | L46: =Orders!K46 -> Bengaluru | M46: =Orders!G46 -> 2480 | N46: =IFERROR(VLOOKUP(Orders!D46,Products!$A$2:$D$61,4,FALSE),"") -> 1173 | O46: =IF(OR(N46="",M46<=0),"",(M46-N46)/M46) -> 0.52701613 | Q46: =Orders!D46 -> PROD-019 | R46: =Products!A46 -> PROD-045 | S46: =SUMIFS($C$2:$C$2001,$H$2:$H$2001,"West",$Q$2:$Q$2001,R46) -> 102894.42
A47: =Orders!A47 -> ORD-00046 | B47: =Orders!B47 -> 45312 | C47: =Orders!I47 -> 31060.26 | D47: =Orders!E47 -> R015 | E47: =IFERROR(VLOOKUP(Orders!D47,Products!$A$2:$C$61,3,FALSE),"Unknown") -> Grocery | F47: =IFERROR(VLOOKUP(Orders!C47,Customers!$A$2:$E$301,5,FALSE),"Unknown") -> SMB | G47: =IFERROR(VLOOKUP(Orders!C47,Customers!$A$2:$C$301,3,FALSE),"") -> 29 | H47: =VLOOKUP(D47,Sales_Reps!$A$2:$C$31,3,FALSE) -> South | I47: =DATE(YEAR(B47),MONTH(B47),1) -> 45292 | L47: =Orders!K47 -> Pune | M47: =Orders!G47 -> 3780 | N47: =IFERROR(VLOOKUP(Orders!D47,Products!$A$2:$D$61,4,FALSE),"") -> 2436 | O47: =IF(OR(N47="",M47<=0),"",(M47-N47)/M47) -> 0.35555556 | Q47: =Orders!D47 -> PROD-027 | R47: =Products!A47 -> PROD-046 | S47: =SUMIFS($C$2:$C$2001,$H$2:$H$2001,"West",$Q$2:$Q$2001,R47) -> 100035.12
... A61: =Orders!A61 -> ORD-00060 | B61: =Orders!B61 -> 45425 | C61: =Orders!I61 -> 13479.64 | D61: =Orders!E61 -> R029 | E61: =IFERROR(VLOOKUP(Orders!D61,Products!$A$2:$C$61,3,FALSE),"Unknown") -> Home | F61: =IFERROR(VLOOKUP(Orders!C61,Customers!$A$2:$E$301,5,FALSE),"Unknown") -> Retail | G61: =IFERROR(VLOOKUP(Orders!C61,Customers!$A$2:$C$301,3,FALSE),"") -> 40 | H61: =VLOOKUP(D61,Sales_Reps!$A$2:$C$31,3,FALSE) -> West | I61: =DATE(YEAR(B61),MONTH(B61),1) -> 45413 | L61: =Orders!K61 -> Mumbai | M61: =Orders!G61 -> 4610 | N61: =IFERROR(VLOOKUP(Orders!D61,Products!$A$2:$D$61,4,FALSE),"") -> 1850 | O61: =IF(OR(N61="",M61<=0),"",(M61-N61)/M61) -> 0.59869848 | Q61: =Orders!D61 -> PROD-039 | R61: =Products!A61 -> PROD-060 | S61: =SUMIFS($C$2:$C$2001,$H$2:$H$2001,"West",$Q$2:$Q$2001,R61) -> 7838.26
A62: =Orders!A62 -> ORD-00061 | B62: =Orders!B62 -> 45589 | C62: =Orders!I62 -> 6186.24 | D62: =Orders!E62 -> R011 | E62: =IFERROR(VLOOKUP(Orders!D62,Products!$A$2:$C$61,3,FALSE),"Unknown") -> Home | F62: =IFERROR(VLOOKUP(Orders!C62,Customers!$A$2:$E$301,5,FALSE),"Unknown") -> SMB | G62: =IFERROR(VLOOKUP(Orders!C62,Customers!$A$2:$C$301,3,FALSE),"") -> 55 | H62: =VLOOKUP(D62,Sales_Reps!$A$2:$C$31,3,FALSE) -> South | I62: =DATE(YEAR(B62),MONTH(B62),1) -> 45566 | L62: =Orders!K62 -> Chennai | M62: =Orders!G62 -> 1080 | N62: =IFERROR(VLOOKUP(Orders!D62,Products!$A$2:$D$61,4,FALSE),"") -> 519 | O62: =IF(OR(N62="",M62<=0),"",(M62-N62)/M62) -> 0.51944444 | Q62: =Orders!D62 -> PROD-040
A63: =Orders!A63 -> ORD-00062 | B63: =Orders!B63 -> 45488 | C63: =Orders!I63 -> 22529.2 | D63: =Orders!E63 -> R006 | E63: =IFERROR(VLOOKUP(Orders!D63,Products!$A$2:$C$61,3,FALSE),"Unknown") -> Beauty | F63: =IFERROR(VLOOKUP(Orders!C63,Customers!$A$2:$E$301,5,FALSE),"Unknown") -> Retail | G63: =IFERROR(VLOOKUP(Orders!C63,Customers!$A$2:$C$301,3,FALSE),"") -> 44 | H63: =VLOOKUP(D63,Sales_Reps!$A$2:$C$31,3,FALSE) -> North | I63: =DATE(YEAR(B63),MONTH(B63),1) -> 45474 | L63: =Orders!K63 -> Pune | M63: =Orders!G63 -> 3020 | N63: =IFERROR(VLOOKUP(Orders!D63,Products!$A$2:$D$61,4,FALSE),"") -> 1626 | O63: =IF(OR(N63="",M63<=0),"",(M63-N63)/M63) -> 0.4615894 | Q63: =Orders!D63 -> PROD-045
A64: =Orders!A64 -> ORD-00063 | B64: =Orders!B64 -> 45465 | C64: =Orders!I64 -> 17633.14 | D64: =Orders!E64 -> R017 | E64: =IFERROR(VLOOKUP(Orders!D64,Products!$A$2:$C$61,3,FALSE),"Unknown") -> Electronics | F64: =IFERROR(VLOOKUP(Orders!C64,Customers!$A$2:$E$301,5,FALSE),"Unknown") -> Corporate | G64: =IFERROR(VLOOKUP(Orders!C64,Customers!$A$2:$C$301,3,FALSE),"") -> 29 | H64: =VLOOKUP(D64,Sales_Reps!$A$2:$C$31,3,FALSE) -> East | I64: =DATE(YEAR(B64),MONTH(B64),1) -> 45444 | L64: =Orders!K64 -> Hyderabad | M64: =Orders!G64 -> 2660 | N64: =IFERROR(VLOOKUP(Orders!D64,Products!$A$2:$D$61,4,FALSE),"") -> 1259 | O64: =IF(OR(N64="",M64<=0),"",(M64-N64)/M64) -> 0.52669173 | Q64: =Orders!D64 -> PROD-008
A65: =Orders!A65 -> ORD-00064 | B65: =Orders!B65 -> 45599 | C65: =Orders!I65 -> 2016.9 | D65: =Orders!E65 -> R003 | E65: =IFERROR(VLOOKUP(Orders!D65,Products!$A$2:$C$61,3,FALSE),"Unknown") -> Electronics | F65: =IFERROR(VLOOKUP(Orders!C65,Customers!$A$2:$E$301,5,FALSE),"Unknown") -> Retail | G65: =IFERROR(VLOOKUP(Orders!C65,Customers!$A$2:$C$301,3,FALSE),"") -> 25 | H65: =VLOOKUP(D65,Sales_Reps!$A$2:$C$31,3,FALSE) -> North | I65: =DATE(YEAR(B65),MONTH(B65),1) -> 45597 | L65: =Orders!K65 -> Pune | M65: =Orders!G65 -> 300 | N65: =IFERROR(VLOOKUP(Orders!D65,Products!$A$2:$D$61,4,FALSE),"") -> 128 | O65: =IF(OR(N65="",M65<=0),"",(M65-N65)/M65) -> 0.57333333 | Q65: =Orders!D65 -> PROD-005
...

Sheet Q4_Pivot
A1: Q4 - PIVOT TABLES (20 marks total)
A2: 2D Pivots · Filters · % of Row Total · Date Grouping · Calculated Fields · Cross-Sheet Data
A4: Q# | B4: Question | C4: Marks | D4: Hint | E4: Your Answer | F4: Format
A5: Q4.1 | B5: Build a pivot with sales_region as rows and product category as columns, values = SUM of final_amount. What value appears at the intersection of "South" and "Electronics"? | C5: 4 | D5: You need to add category (from Products) and region (from Sales_Reps) as columns to Orders first. Insert PivotTable from combined data. | E5: =GETPIVOTDATA("Final Amount",Sheet2!$A$3,"Sales Region","South","Category","Electronics") -> 1314107.4 | F5: Currency
A6: Q4.2 | B6: Build a pivot: rows = order month (Jan-24 through Dec-24), columns = sales_rep_id, values = SUM of final_amount. What is the HIGHEST single value in the entire pivot? (One number.) | C6: 4 | D6: After building, use MAX() over the pivot data range, or scan visually. | E6: =MAX(Sheet3!B5:M34) -> 216421.52 | F6: Currency
